<mujoco model="quadruped_model_onground">
  <!-- defaults -->
  <compiler angle="radian"/>

  <option timestep="0.001" integrator="implicitfast"/>

  <size nstack="300000" nuser_geom="1"/>

  <default>
    <joint solimplimit="0 0.8 0.03" stiffness="8" limited="true" armature="0.1" damping="0.01"/>
    <geom conaffinity="0" friction="1 0.1 0.1" rgba="0.8 0.6 0.4 1"/>
    <general ctrllimited="true" ctrlrange="0 1" dyntype="muscle" dynprm="0.01 0.04 0 0 0 0 0 0 0 0" gaintype="muscle" biastype="muscle" gainprm="0.75 1.05 -1 200 0.5 1.6 1.5 1.3 1.2" biasprm="0.75 1.05 -1 200 0.5 1.6 1.5 1.3 1.2"/>
    <default class="ground-hard">
      <geom conaffinity="1" friction="1 0.005 0.0001" solref="0.05" solimp="0"/>
    </default>
    <default class="ground-soft">
      <geom conaffinity="1" friction="1 0.005 0.0001" solref="0.1" solimp="0 0.95 0.005 0.25 1.5"/>
    </default>
    <default class="ground-very_soft">
      <geom conaffinity="1" friction="1 0.005 0.0001" solref="0.1" solimp="0 0.95 0.1 0.25 1.5"/>
    </default>
    <default class="foot">
      <geom conaffinity="1" friction="1 0.005 0.0001" solimp="0 0.95 0.005"/>
    </default>
  </default>

  <asset>
    <texture type="skybox" builtin="gradient" rgb1="1 1 1" rgb2="0 0 0" width="100" height="600"/>
    <texture type="cube" name="texgeom" builtin="flat" mark="cross" rgb1="0.8 0.6 0.4" rgb2="0.8 0.6 0.4" markrgb="1 1 1" width="127" height="762"/>
    <texture type="2d" name="texplane" builtin="flat" rgb1="0.4 0.26 0.16" width="100" height="100"/>
    <material name="MatPlane" texture="texplane" specular="1" shininess="1"/>
    <material name="geom" texture="texgeom" texuniform="true"/>
  </asset>

  <worldbody>
    <geom name="floor" class="ground-hard" size="40 40 40" type="plane" material="MatPlane" rgba="0.8 0.8 0.8 1"/>
    <camera name="world_cam" pos="-0.605 -3.986 0.399" quat="0.738905 0.669601 -0.05049 -0.0557157"/>
    <light pos="0 0 1.3" dir="0 0 -1" directional="true" cutoff="100" exponent="1" diffuse="1 1 1" specular="0.1 0.1 0.1"/>
    <light pos="0 0 1.3" dir="0 0 -1" directional="true" cutoff="100" exponent="1" diffuse="1 1 1" specular="0.1 0.1 0.1"/>
    <body name="body" pos="0 0 0.5">
      <joint name="rootx" pos="0 0 0" axis="1 0 0" type="slide" stiffness="0" limited="false" armature="0" damping="0"/>
      <joint name="rootz" pos="0 0 0" axis="0 0 1" type="slide" stiffness="0" limited="false" armature="0" damping="0"/>
      <joint name="root_rot" pos="0 0 0" axis="0 1 0" stiffness="1" range="-1.5 1.5" armature="0" damping="1.5"/>
      <geom name="torso" size="0.5 0.26 0.05" type="box" mass="0.4"/>
      <geom name="neck" size="0.046 0.075" pos="0.5 0 0.075" quat="0.90687 0 0.42141 0" type="capsule" mass="0.025"/>
      <geom name="head" size="0.08 0.095 0.2" pos="0.6 0 0.18" quat="0.659983 0 0.75128 0" type="ellipsoid" mass="0.025"/>
      <geom name="tail" size="0.026 0.035" pos="-0.53 0 0.075" quat="0.90687 0 -0.42141 0" type="capsule" mass="0.05"/>
      <site name="SITE_RB_0" pos="-0.35 -0.25 0.25" size="0.01"/>
      <site name="SITE_RB_1" pos="-0.65 -0.25 0.15" size="0.01"/>
      <site name="SITE_RB_2" pos="-0.35 -0.25 0.15" size="0.01"/>
      <site name="SITE_RF_0" pos="0.65 -0.25 0.25" size="0.01"/>
      <site name="SITE_RF_1" pos="0.35 -0.25 0.15" size="0.01"/>
      <site name="SITE_RF_2" pos="0.65 -0.25 0.15" size="0.01"/>
      <site name="SITE_LB_0" pos="-0.35 0.25 0.25" size="0.01"/>
      <site name="SITE_LB_1" pos="-0.65 0.25 0.15" size="0.01"/>
      <site name="SITE_LB_2" pos="-0.35 0.25 0.15" size="0.01"/>
      <site name="SITE_LF_0" pos="0.65 0.25 0.25" size="0.01"/>
      <site name="SITE_LF_1" pos="0.35 0.25 0.15" size="0.01"/>
      <site name="SITE_LF_2" pos="0.65 0.25 0.15" size="0.01"/>
      <camera name="track" pos="0 -3 0.3" quat="0.707107 0.707107 0 0" mode="trackcom"/>
      <body name="rbthigh" pos="-0.5 -0.25 0">
        <joint name="rbthigh" pos="0 0 0" axis="0 1 0" stiffness="0" range="-1 0.7" damping="1.5"/>
        <geom name="RB_HIP" size="0.075 0.05" quat="0.707107 -0.707107 0 0" type="cylinder" mass="0.03125" rgba="1 1 1 0.5"/>
        <geom name="rbthigh" size="0.04497 0.13003" pos="-0.07 0 -0.12" quat="0.96639 0 0.257081 0" type="capsule" mass="0.03125"/>
        <site name="SIDESITE_RB_0" pos="-0.105 0 0.1179" size="0.01" group="1" rgba="0.7 0.8 0.95 0.8"/>
        <site name="SIDESITE_RB_1" pos="0.155 0 -0.0311" size="0.01" group="1" rgba="0.7 0.8 0.95 0.8"/>
        <site name="SITE_RB_3" pos="0.0012 0 -0.0986" size="0.01"/>
        <site name="SITE_RB_4" pos="-0.132 0 -0.0708" size="0.01"/>
        <site name="SITE_RB_5" pos="-0.0661 0 -0.1154" size="0.01"/>
        <body name="rbshin" pos="-0.14 0 -0.24">
          <joint name="rbshin" pos="0 0 0" axis="0 1 0" stiffness="0" range="-1.2 0.87" damping="1"/>
          <geom name="RB_KNEE" size="0.075 0.05" quat="0.707107 -0.707107 0 0" type="cylinder" mass="0.03125" rgba="1 1 1 0.5"/>
          <geom name="rbshin" size="0.03783 0.08717" pos="0.065 0 -0.09" quat="0.955336 0 -0.29552 0" type="capsule" mass="0.03125" rgba="0.9 0.6 0.6 1"/>
          <site name="SIDESITE_RB_2" pos="-0.1238 0 -0.0847" size="0.01" group="1" rgba="0.7 0.8 0.95 0.8"/>
          <site name="SIDESITE_RB_3" pos="0.1238 0 0.0847" size="0.01" group="1" rgba="0.7 0.8 0.95 0.8"/>
          <site name="SITE_RB_6" pos="0.0067 0 -0.0984" size="0.01"/>
          <site name="SITE_RB_7" pos="0.0893 0 -0.0419" size="0.01"/>
          <body name="rbfoot" pos="0.14 0 -0.2">
            <geom name="rbfoot" class="foot" size="0.025" mass="0.0001" rgba="0.9 0.3 0.3 1"/>
            <site name="rbfoot_touch_sensor_site" pos="0 0 0" quat="0.955337 0 -0.29552 0" size="0.04 0.01" type="capsule" rgba="0 1 0 0.1"/>
          </body>
        </body>
      </body>
      <body name="rfthigh" pos="0.5 -0.25 0">
        <joint name="rfthigh" pos="0 0 0" axis="0 1 0" stiffness="0" range="-1 0.7" damping="1.5"/>
        <geom name="RF_HIP" size="0.075 0.05" quat="0.707107 -0.707107 0 0" type="cylinder" mass="0.03125" rgba="1 1 1 0.5"/>
        <geom name="rfthigh" size="0.04497 0.13003" pos="-0.07 0 -0.12" quat="0.96639 0 0.257081 0" type="capsule" mass="0.03125"/>
        <site name="SIDESITE_RF_0" pos="-0.105 0 0.1179" size="0.01" group="1" rgba="0.7 0.8 0.95 0.8"/>
        <site name="SIDESITE_RF_1" pos="0.155 0 -0.0311" size="0.01" group="1" rgba="0.7 0.8 0.95 0.8"/>
        <site name="SITE_RF_3" pos="0.0012 0 -0.0986" size="0.01"/>
        <site name="SITE_RF_4" pos="-0.132 0 -0.0708" size="0.01"/>
        <site name="SITE_RF_5" pos="-0.0661 0 -0.1154" size="0.01"/>
        <body name="rfshin" pos="-0.14 0 -0.24">
          <joint name="rfshin" pos="0 0 0" axis="0 1 0" stiffness="0" range="-1.2 0.87" damping="1"/>
          <geom name="RF_KNEE" size="0.075 0.05" quat="0.707107 -0.707107 0 0" type="cylinder" mass="0.03125" rgba="1 1 1 0.5"/>
          <geom name="rfshin" size="0.03783 0.08717" pos="0.065 0 -0.09" quat="0.955336 0 -0.29552 0" type="capsule" mass="0.03125" rgba="0.9 0.6 0.6 1"/>
          <site name="SIDESITE_RF_2" pos="-0.1238 0 -0.0847" size="0.01" group="1" rgba="0.7 0.8 0.95 0.8"/>
          <site name="SIDESITE_RF_3" pos="0.1238 0 0.0847" size="0.01" group="1" rgba="0.7 0.8 0.95 0.8"/>
          <site name="SITE_RF_6" pos="0.0067 0 -0.0984" size="0.01"/>
          <site name="SITE_RF_7" pos="0.0893 0 -0.0419" size="0.01"/>
          <body name="rffoot" pos="0.14 0 -0.2">
            <geom name="rffoot" class="foot" size="0.025" mass="0.0001" rgba="0.9 0.3 0.3 1"/>
            <site name="rffoot_touch_sensor_site" pos="0 0 0" quat="0.955337 0 -0.29552 0" size="0.04 0.01" type="capsule" rgba="0 1 0 0.1"/>
          </body>
        </body>
      </body>
      <body name="lbthigh" pos="-0.5 0.25 0">
        <joint name="lbthigh" pos="0 0 0" axis="0 1 0" stiffness="0" range="-1 0.7" damping="1.5"/>
        <geom name="LB_HIP" size="0.075 0.05" quat="0.707107 -0.707107 0 0" type="cylinder" mass="0.03125" rgba="1 1 1 0.5"/>
        <geom name="lbthigh" size="0.04497 0.13003" pos="-0.07 0 -0.12" quat="0.96639 0 0.257081 0" type="capsule" mass="0.03125"/>
        <site name="SIDESITE_LB_0" pos="-0.105 0 0.1179" size="0.01" group="1" rgba="0.7 0.8 0.95 0.8"/>
        <site name="SIDESITE_LB_1" pos="0.155 0 -0.0311" size="0.01" group="1" rgba="0.7 0.8 0.95 0.8"/>
        <site name="SITE_LB_3" pos="0.0012 0 -0.0986" size="0.01"/>
        <site name="SITE_LB_4" pos="-0.132 0 -0.0708" size="0.01"/>
        <site name="SITE_LB_5" pos="-0.0661 0 -0.1154" size="0.01"/>
        <body name="lbshin" pos="-0.14 0 -0.24">
          <joint name="lbshin" pos="0 0 0" axis="0 1 0" stiffness="0" range="-1.2 0.87" damping="1"/>
          <geom name="LB_KNEE" size="0.075 0.05" quat="0.707107 -0.707107 0 0" type="cylinder" mass="0.03125" rgba="1 1 1 0.5"/>
          <geom name="lbshin" size="0.03783 0.08717" pos="0.065 0 -0.09" quat="0.955336 0 -0.29552 0" type="capsule" mass="0.03125" rgba="0.9 0.6 0.6 1"/>
          <site name="SIDESITE_LB_2" pos="-0.1238 0 -0.0847" size="0.01" group="1" rgba="0.7 0.8 0.95 0.8"/>
          <site name="SIDESITE_LB_3" pos="0.1238 0 0.0847" size="0.01" group="1" rgba="0.7 0.8 0.95 0.8"/>
          <site name="SITE_LB_6" pos="0.0067 0 -0.0984" size="0.01"/>
          <site name="SITE_LB_7" pos="0.0893 0 -0.0419" size="0.01"/>
          <body name="lbfoot" pos="0.14 0 -0.2">
            <geom name="lbfoot" class="foot" size="0.025" mass="0.0001" rgba="0.9 0.3 0.3 1"/>
            <site name="lbfoot_touch_sensor_site" pos="0 0 0" quat="0.955337 0 -0.29552 0" size="0.04 0.01" type="capsule" rgba="0 1 0 0.1"/>
          </body>
        </body>
      </body>
      <body name="lfthigh" pos="0.5 0.25 0">
        <joint name="lfthigh" pos="0 0 0" axis="0 1 0" stiffness="0" range="-1 0.7" damping="1.5"/>
        <geom name="LF_HIP" size="0.075 0.05" quat="0.707107 -0.707107 0 0" type="cylinder" mass="0.03125" rgba="1 1 1 0.5"/>
        <geom name="lfthigh" size="0.04497 0.13003" pos="-0.07 0 -0.12" quat="0.96639 0 0.257081 0" type="capsule" mass="0.03125"/>
        <site name="SIDESITE_LF_0" pos="-0.105 0 0.1179" size="0.01" group="1" rgba="0.7 0.8 0.95 0.8"/>
        <site name="SIDESITE_LF_1" pos="0.155 0 -0.0311" size="0.01" group="1" rgba="0.7 0.8 0.95 0.8"/>
        <site name="SITE_LF_3" pos="0.0012 0 -0.0986" size="0.01"/>
        <site name="SITE_LF_4" pos="-0.132 0 -0.0708" size="0.01"/>
        <site name="SITE_LF_5" pos="-0.0661 0 -0.1154" size="0.01"/>
        <body name="lfshin" pos="-0.14 0 -0.24">
          <joint name="lfshin" pos="0 0 0" axis="0 1 0" stiffness="0" range="-1.2 0.87" damping="1"/>
          <geom name="LF_KNEE" size="0.075 0.05" quat="0.707107 -0.707107 0 0" type="cylinder" mass="0.03125" rgba="1 1 1 0.5"/>
          <geom name="lfshin" size="0.03783 0.08717" pos="0.065 0 -0.09" quat="0.955336 0 -0.29552 0" type="capsule" mass="0.03125" rgba="0.9 0.6 0.6 1"/>
          <site name="SIDESITE_LF_2" pos="-0.1238 0 -0.0847" size="0.01" group="1" rgba="0.7 0.8 0.95 0.8"/>
          <site name="SIDESITE_LF_3" pos="0.1238 0 0.0847" size="0.01" group="1" rgba="0.7 0.8 0.95 0.8"/>
          <site name="SITE_LF_6" pos="0.0067 0 -0.0984" size="0.01"/>
          <site name="SITE_LF_7" pos="0.0893 0 -0.0419" size="0.01"/>
          <body name="lffoot" pos="0.14 0 -0.2">
            <geom name="lffoot" class="foot" size="0.025" mass="0.0001" rgba="0.9 0.3 0.3 1"/>
            <site name="lffoot_touch_sensor_site" pos="0 0 0" quat="0.955337 0 -0.29552 0" size="0.04 0.01" type="capsule" rgba="0 1 0 0.1"/>
          </body>
        </body>
      </body>
    </body>
  </worldbody>

  <tendon>
    <spatial name="T_RB_M0" width="0.006" rgba="0.55 0.78 0.55 1">
      <site site="SITE_RB_0"/>
      <geom geom="RB_HIP" sidesite="SIDESITE_RB_0"/>
      <site site="SITE_RB_5"/>
      <geom geom="RB_KNEE" sidesite="SIDESITE_RB_3"/>
      <site site="SITE_RB_7"/>
    </spatial>
    <spatial name="T_RB_M1" width="0.006" rgba="0.95 0.5 0.47 1">
      <site site="SITE_RB_1"/>
      <geom geom="RB_HIP" sidesite="SIDESITE_RB_1"/>
      <site site="SITE_RB_3"/>
    </spatial>
    <spatial name="T_RB_M2" width="0.006" rgba="0.45 0.49 0.83 1">
      <site site="SITE_RB_2"/>
      <geom geom="RB_HIP" sidesite="SIDESITE_RB_0"/>
      <site site="SITE_RB_4"/>
      <geom geom="RB_KNEE" sidesite="SIDESITE_RB_2"/>
      <site site="SITE_RB_6"/>
    </spatial>
    <spatial name="T_RF_M0" width="0.006" rgba="0.55 0.78 0.55 1">
      <site site="SITE_RF_0"/>
      <geom geom="RF_HIP" sidesite="SIDESITE_RF_0"/>
      <site site="SITE_RF_5"/>
      <geom geom="RF_KNEE" sidesite="SIDESITE_RF_3"/>
      <site site="SITE_RF_7"/>
    </spatial>
    <spatial name="T_RF_M1" width="0.006" rgba="0.95 0.5 0.47 1">
      <site site="SITE_RF_1"/>
      <geom geom="RF_HIP" sidesite="SIDESITE_RF_1"/>
      <site site="SITE_RF_3"/>
    </spatial>
    <spatial name="T_RF_M2" width="0.006" rgba="0.45 0.49 0.83 1">
      <site site="SITE_RF_2"/>
      <geom geom="RF_HIP" sidesite="SIDESITE_RF_0"/>
      <site site="SITE_RF_4"/>
      <geom geom="RF_KNEE" sidesite="SIDESITE_RF_2"/>
      <site site="SITE_RF_6"/>
    </spatial>
    <spatial name="T_LB_M0" width="0.006" rgba="0.55 0.78 0.55 1">
      <site site="SITE_LB_0"/>
      <geom geom="LB_HIP" sidesite="SIDESITE_LB_0"/>
      <site site="SITE_LB_5"/>
      <geom geom="LB_KNEE" sidesite="SIDESITE_LB_3"/>
      <site site="SITE_LB_7"/>
    </spatial>
    <spatial name="T_LB_M1" width="0.006" rgba="0.95 0.5 0.47 1">
      <site site="SITE_LB_1"/>
      <geom geom="LB_HIP" sidesite="SIDESITE_LB_1"/>
      <site site="SITE_LB_3"/>
    </spatial>
    <spatial name="T_LB_M2" width="0.006" rgba="0.45 0.49 0.83 1">
      <site site="SITE_LB_2"/>
      <geom geom="LB_HIP" sidesite="SIDESITE_LB_0"/>
      <site site="SITE_LB_4"/>
      <geom geom="LB_KNEE" sidesite="SIDESITE_LB_2"/>
      <site site="SITE_LB_6"/>
    </spatial>
    <spatial name="T_LF_M0" width="0.006" rgba="0.55 0.78 0.55 1">
      <site site="SITE_LF_0"/>
      <geom geom="LF_HIP" sidesite="SIDESITE_LF_0"/>
      <site site="SITE_LF_5"/>
      <geom geom="LF_KNEE" sidesite="SIDESITE_LF_3"/>
      <site site="SITE_LF_7"/>
    </spatial>
    <spatial name="T_LF_M1" width="0.006" rgba="0.95 0.5 0.47 1">
      <site site="SITE_LF_1"/>
      <geom geom="LF_HIP" sidesite="SIDESITE_LF_1"/>
      <site site="SITE_LF_3"/>
    </spatial>
    <spatial name="T_LF_M2" width="0.006" rgba="0.45 0.49 0.83 1">
      <site site="SITE_LF_2"/>
      <geom geom="LF_HIP" sidesite="SIDESITE_LF_0"/>
      <site site="SITE_LF_4"/>
      <geom geom="LF_KNEE" sidesite="SIDESITE_LF_2"/>
      <site site="SITE_LF_6"/>
    </spatial>
  </tendon>

  <actuator>
    <general name="T_RB_M0" tendon="T_RB_M0" lengthrange="0.459547 0.768536" gainprm="0.5 1.5 100 200 0.5 1.5 1.6" biasprm="0.5 1.5 100 200 0.5 1.5 1.6"/>
    <general name="T_RB_M1" tendon="T_RB_M1" lengthrange="0.336191 0.466032" gainprm="0.5 1.5 100 200 0.5 1.5 1.6" biasprm="0.5 1.5 100 200 0.5 1.5 1.6"/>
    <general name="T_RB_M2" tendon="T_RB_M2" lengthrange="0.575756 0.863523" gainprm="0.5 1.5 250 200 0.5 1.5 1.6" biasprm="0.5 1.5 250 200 0.5 1.5 1.6"/>
    <general name="T_RF_M0" tendon="T_RF_M0" lengthrange="0.459547 0.768536" gainprm="0.5 1.5 100 200 0.5 1.5 1.6" biasprm="0.5 1.5 100 200 0.5 1.5 1.6"/>
    <general name="T_RF_M1" tendon="T_RF_M1" lengthrange="0.336191 0.466032" gainprm="0.5 1.5 100 200 0.5 1.5 1.6" biasprm="0.5 1.5 100 200 0.5 1.5 1.6"/>
    <general name="T_RF_M2" tendon="T_RF_M2" lengthrange="0.575756 0.863523" gainprm="0.5 1.5 250 200 0.5 1.5 1.6" biasprm="0.5 1.5 250 200 0.5 1.5 1.6"/>
    <general name="T_LB_M0" tendon="T_LB_M0" lengthrange="0.459547 0.768536" gainprm="0.5 1.5 100 200 0.5 1.5 1.6" biasprm="0.5 1.5 100 200 0.5 1.5 1.6"/>
    <general name="T_LB_M1" tendon="T_LB_M1" lengthrange="0.336191 0.466032" gainprm="0.5 1.5 100 200 0.5 1.5 1.6" biasprm="0.5 1.5 100 200 0.5 1.5 1.6"/>
    <general name="T_LB_M2" tendon="T_LB_M2" lengthrange="0.575756 0.863523" gainprm="0.5 1.5 250 200 0.5 1.5 1.6" biasprm="0.5 1.5 250 200 0.5 1.5 1.6"/>
    <general name="T_LF_M0" tendon="T_LF_M0" lengthrange="0.459547 0.768536" gainprm="0.5 1.5 100 200 0.5 1.5 1.6" biasprm="0.5 1.5 100 200 0.5 1.5 1.6"/>
    <general name="T_LF_M1" tendon="T_LF_M1" lengthrange="0.336191 0.466032" gainprm="0.5 1.5 100 200 0.5 1.5 1.6" biasprm="0.5 1.5 100 200 0.5 1.5 1.6"/>
    <general name="T_LF_M2" tendon="T_LF_M2" lengthrange="0.575756 0.863523" gainprm="0.5 1.5 250 200 0.5 1.5 1.6" biasprm="0.5 1.5 250 200 0.5 1.5 1.6"/>
  </actuator>

  <sensor>
    <touch site="rbfoot_touch_sensor_site" name="rbfoot_touch_sensor"/>
    <touch site="rffoot_touch_sensor_site" name="rffoot_touch_sensor"/>
    <touch site="lbfoot_touch_sensor_site" name="lbfoot_touch_sensor"/>
    <touch site="lffoot_touch_sensor_site" name="lffoot_touch_sensor"/>
  </sensor>
</mujoco>
